Workbook

Sheet 1_Cover_Assumptions
A1: Defence Innovation Loan FY26/27 Cycle 1 - Project Finance Model
A3: Applicant: | B3: Safetech Global Limited (trading as OTShield)
A4: Programme: | B4: UKDI Defence Innovation Loan FY26/27 - Cycle 1
A5: Submission deadline: | B5: 12:00 BST Tue 19 May 2026
A6: Stage 1 decision: | B6: 07 Jul 2026 (feedback 28 Jul 2026)
A7: Innovation Outline ID: | B7: DIOL227223
A8: Innovation Partner: | B8: Paul Wright (UKDI)
A9: Reference document: UKDI Defence Innovation Loan FY26/27 Cycle 1 Competition Doc (updated 14 Apr 2026)
A10: Loan Parameters (Cycle 1 published terms)
A11: Loan amount (£) | B11: 700000 | D11: Within Cycle 1 maximum (£1M); calibrated to lean delivery profile
A12: Project period (months) | B12: 18 | D12: 18-month commercialisation push; within Cycle 1 3-year cap
A13: Repayment period (months) | B13: 60 | D13: 5 years post-project; total term 6.5 yrs (within 7-yr cap)
A14: Project start (planned) | B14: 01-Oct-2026 | D14: Indicative; actual start follows Innovate UK Loans Ltd contract
A15: Project end (planned) | B15: 31-Mar-2028 | D15: Project end at month 18 (M18)
A16: Repayment start (planned) | B16: 01-Apr-2028 | D16: Repayment starts immediately after project (no deferred year)
A17: Repayment end (planned) | B17: 31-Mar-2033 | D17: Loan fully repaid; total term 6.5 years from project start
A18: Drawdown frequency | B18: Quarterly | D18: 6 quarterly tranches over 18 months
A19: Interest rate - project period | B19: 0.037 | D19: 3.7% during 18-month project period (indicative; confirm at Stage 2)
A20: Interest rate - deferred (post-project, pre-repay) | B20: 0.037 | D20: Per Competition Doc §5: 3.7% accrued and deferred until repayment (additional to quarterly interest paid)
A21: Interest rate - repayment period | B21: 0.074 | D21: 7.4% during 5-yr repayment (indicative; confirm at Stage 2)
A22: Subsidy Intensity & Compliance Targets
A23: Subsidy intensity cap (small business per Competition Doc §9.1) | B23: 0.45 | D23: Cycle 1 rule: small/micro SME = 45%; medium SME = 35%
A24: Liquidity ratio target (current assets / current liabilities) | B24: 1.1 | D24: must be ≥ 1.1:1 throughout project
A25: Team Cost Assumptions (loan-funded portion)
A26: Role | B26: Annual £ | C26: FTE | D26: Months on project | E26: Cost £
A27: Fatma Erturk - CEO | B27: 120000 | C27: 1 | D27: 18 | E27: =B27*C27*D27/12 -> 180000
A28: [CTO Name] - CTO (new hire, M1-M3 onboarding) | B28: 110000 | C28: 1 | D28: 16 | E28: =B28*C28*D28/12 -> 146666.67
A29: Alan Jenkins - Cyber Security Advisor | B29: 208000 | C29: 0.2 | D29: 18 | E29: =B29*C29*D29/12 -> 62400
A30: Jon Medvenics - Senior Cyber Security Expert and AI Verifier | B30: 132000 | C30: 0.5 | D30: 18 | E30: =B30*C30*D30/12 -> 99000
A31: Diana Polansky - Marketing Advisor | B31: 110000 | C31: 0.5 | D31: 18 | E31: =B31*C31*D31/12 -> 82500
A32: Henrique Santos - Junior Marketing & Customer Success Lead (dual role) | B32: 35000 | C32: 1 | D32: 18 | E32: =B32*C32*D32/12 -> 52500
A33: Dhruv Rathod - Junior Cyber Security Engineer | B33: 33000 | C33: 1 | D33: 18 | E33: =B33*C33*D33/12 -> 49500
A34: Subtotal - internal team | E34: =SUM(E27:E33) -> 672566.67
A36: Other Project Costs (loan-funded)
A37: Item
A38: Cloud / lab infrastructure (UK sovereign) | E38: 50000
A39: ICS hardware (PLCs, RTUs, HMI test rigs) | E39: 35000
A40: Pen-test / IEC 62443 assurance | E40: 25000
A41: Travel & customer pilots (UK CNI sites + 2 defence refs) | E41: 15000
A42: Legal / IP / patents | E42: 10000
...

Sheet 2_Drawdown_Schedule
A1: Quarterly Drawdown Schedule - £700K over 18 months
A3: Tranche | B3: Quarter | C3: Date | D3: Drawdown £ | E3: Cumulative £ | F3: Milestone gate
A4: 1 | B4: Q1 (M1-M3) | C4: 01-Oct-2026 | D4: 140000 | E4: =D4 -> 140000 | F4: Mobilisation: CTO onboarded, sovereign UK lab live
A5: 2 | B5: Q2 (M4-M6) | C5: 01-Jan-2027 | D5: 140000 | E5: =E4+D5 -> 280000 | F5: M6: deception telemetry → TAXII/MISP feed live
A6: 3 | B6: Q3 (M7-M9) | C6: 01-Apr-2027 | D6: 120000 | E6: =E5+D6 -> 400000 | F6: M9: first CNI lighthouse pilot (utility) signed
A7: 4 | B7: Q4 (M10-M12) | C7: 01-Jul-2027 | D7: 120000 | E7: =E6+D7 -> 520000 | F7: M12: 3 CNI pilots running, IEC 62443 stage gate
A8: 5 | B8: Q5 (M13-M15) | C8: 01-Oct-2027 | D8: 100000 | E8: =E7+D8 -> 620000 | F8: M15: 1st defence reference environment live
A9: 6 | B9: Q6 (M16-M18) | C9: 01-Jan-2028 | D9: 80000 | E9: =E8+D9 -> 700000 | F9: M18: TRL 9, 5 CNI lighthouses + 2 defence refs, £350K ARR
A10: TOTAL | D10: =SUM(D4:D9) -> 700000 | E10: =E9 -> 700000

Sheet 3_Interest_Repayment
A1: Interest Accrual + Repayment Schedule (Y1-Y8)
A3: Period | B3: Phase | C3: Opening balance £ | D3: Drawdowns £ | E3: Interest rate | F3: Interest accrued £ | G3: Principal repaid £ | H3: Interest paid £ | I3: Closing balance £
A4: Y1 Oct26-Sep27 | B4: Project (Yr1) | C4: 0 | D4: 520000 | E4: ='1_Cover_Assumptions'!$B$19 -> 0.037 | F4: =(C4+D4/2)*E4 -> 9620 | G4: 0 | H4: 0 | I4: =C4+D4+F4-G4-H4 -> 529620
A5: Y2 Oct27-Mar28 | B5: Project (Yr2 H1) | C5: =I4 -> 529620 | D5: 180000 | E5: ='1_Cover_Assumptions'!$B$19*0.5 -> 0.0185 | F5: =(C5+D5/2)*E5 -> 11462.97 | G5: 0 | H5: 0 | I5: =C5+D5+F5-G5-H5 -> 721082.97
A6: Repay Y1 (Apr28-Mar29) | B6: Repayment Yr1 | C6: =I5 -> 721082.97 | D6: 0 | E6: ='1_Cover_Assumptions'!$B$21 -> 0.074 | F6: =C6*E6 -> 53360.14 | G6: =$I$5/5 -> 144216.59 | H6: =F6 -> 53360.14 | I6: =C6+D6+F6-G6-H6 -> 576866.38
A7: Repay Y2 (Apr29-Mar30) | B7: Repayment Yr2 | C7: =I6 -> 576866.38 | D7: 0 | E7: ='1_Cover_Assumptions'!$B$21 -> 0.074 | F7: =C7*E7 -> 42688.112 | G7: =$I$5/5 -> 144216.59 | H7: =F7 -> 42688.112 | I7: =C7+D7+F7-G7-H7 -> 432649.78
A8: Repay Y3 (Apr30-Mar31) | B8: Repayment Yr3 | C8: =I7 -> 432649.78 | D8: 0 | E8: ='1_Cover_Assumptions'!$B$21 -> 0.074 | F8: =C8*E8 -> 32016.084 | G8: =$I$5/5 -> 144216.59 | H8: =F8 -> 32016.084 | I8: =C8+D8+F8-G8-H8 -> 288433.19
A9: Repay Y4 (Apr31-Mar32) | B9: Repayment Yr4 | C9: =I8 -> 288433.19 | D9: 0 | E9: ='1_Cover_Assumptions'!$B$21 -> 0.074 | F9: =C9*E9 -> 21344.056 | G9: =$I$5/5 -> 144216.59 | H9: =F9 -> 21344.056 | I9: =C9+D9+F9-G9-H9 -> 144216.59
A10: Repay Y5 (Apr32-Mar33) | B10: Repayment Yr5 | C10: =I9 -> 144216.59 | D10: 0 | E10: ='1_Cover_Assumptions'!$B$21 -> 0.074 | F10: =C10*E10 -> 10672.028 | G10: =$I$5/5 -> 144216.59 | H10: =F10 -> 10672.028 | I10: =C10+D10+F10-G10-H10 -> 1.1459633e-10
A11: TOTALS | D11: =SUM(D4:D10) -> 700000 | F11: =SUM(F4:F10) -> 181163.39 | G11: =SUM(G4:G10) -> 721082.97 | H11: =SUM(H4:H10) -> 160080.42
A13: Notes:
A14: 1) Cycle 1 published rates: 3.7% during 18-month project + 3.7% on outstanding during deferred period + 7.4% during 5-yr repayment.
A15: 2) Project ends 31 Mar 2028 (M18). Repayment starts 01 Apr 2028 (no deferred gap year in this plan).
A16: 3) Equal annual principal repayment ~£144,217 + accrued interest paid annually. Closing balance reaches zero by end of Repay Y5.
A17: 4) Drawdowns shown annually; per quarterly schedule see sheet 2_Drawdown_Schedule.
A18: 5) Interest in project years uses mid-period convention (drawdowns weighted at 50%).

Sheet 4_PnL_Forecast
A1: Profit & Loss Forecast - Y1 (FY26) to Y7 (FY32)
A3: £ thousands | B3: FY26 (Y1) | C3: FY27 (Y2) | D3: FY28 (Y3) | E3: FY29 (Y4) | F3: FY30 (Y5) | G3: FY31 (Y6) | H3: FY32 (Y7)
A4: Recurring ARR - UK CNI lighthouses | B4: 0 | C4: 150 | D4: 450 | E4: 1200 | F4: 2400 | G4: 4200 | H4: 6800
A5: Recurring ARR - Defence reference | B5: 0 | C5: 50 | D5: 200 | E5: 500 | F5: 900 | G5: 1500 | H5: 2400
A6: Recurring ARR - International CNI | B6: 0 | C6: 0 | D6: 100 | E6: 400 | F6: 900 | G6: 1800 | H6: 3200
A7: Professional services / pilots | B7: 50 | C7: 150 | D7: 300 | E7: 500 | F7: 700 | G7: 900 | H7: 1100
A8: Threat-intel feed (TAXII/MISP) | B8: 0 | C8: 30 | D8: 90 | E8: 200 | F8: 400 | G8: 650 | H8: 950
A9: Total Revenue | B9: =SUM(B4:B8) -> 50 | C9: =SUM(C4:C8) -> 380 | D9: =SUM(D4:D8) -> 1140 | E9: =SUM(E4:E8) -> 2800 | F9: =SUM(F4:F8) -> 5300 | G9: =SUM(G4:G8) -> 9050 | H9: =SUM(H4:H8) -> 14450
A11: Cost of Sales (COGS)
A12: Cloud & infrastructure | B12: 30 | C12: 55 | D12: 95 | E12: 160 | F12: 280 | G12: 450 | H12: 680
A13: ICS hardware & lab | B13: 20 | C13: 30 | D13: 40 | E13: 55 | F13: 75 | G13: 100 | H13: 140
A14: Customer support & success | B14: 10 | C14: 18 | D14: 50 | E14: 130 | F14: 270 | G14: 460 | H14: 720
A15: Total COGS | B15: =SUM(B12:B14) -> 60 | C15: =SUM(C12:C14) -> 103 | D15: =SUM(D12:D14) -> 185 | E15: =SUM(E12:E14) -> 345 | F15: =SUM(F12:F14) -> 625 | G15: =SUM(G12:G14) -> 1010 | H15: =SUM(H12:H14) -> 1540
A17: Gross Profit | B17: =B9-B15 -> -10 | C17: =C9-C15 -> 277 | D17: =D9-D15 -> 955 | E17: =E9-E15 -> 2455 | F17: =F9-F15 -> 4675 | G17: =G9-G15 -> 8040 | H17: =H9-H15 -> 12910
A18: Gross margin % | B18: =IFERROR(B17/B9,0) -> -0.2 | C18: =IFERROR(C17/C9,0) -> 0.72894737 | D18: =IFERROR(D17/D9,0) -> 0.8377193 | E18: =IFERROR(E17/E9,0) -> 0.87678571 | F18: =IFERROR(F17/F9,0) -> 0.88207547 | G18: =IFERROR(G17/G9,0) -> 0.88839779 | H18: =IFERROR(H17/H9,0) -> 0.89342561
A20: Operating Expenses
A21: Personnel - engineering | B21: 110 | C21: 230 | D21: 350 | E21: 580 | F21: 860 | G21: 1160 | H21: 1460
A22: Personnel - commercial & marketing | B22: 40 | C22: 60 | D22: 110 | E22: 220 | F22: 360 | G22: 520 | H22: 700
A23: Personnel - G&A / leadership | B23: 110 | C23: 160 | D23: 210 | E23: 270 | F23: 330 | G23: 390 | H23: 450
A24: Marketing & customer acquisition | B24: 15 | C24: 35 | D24: 70 | E24: 130 | F24: 220 | G24: 340 | H24: 490
A25: Travel & events | B25: 10 | C25: 18 | D25: 35 | E25: 60 | F25: 90 | G25: 120 | H25: 160
A26: Legal / IP / compliance / audit | B26: 20 | C26: 35 | D26: 55 | E26: 75 | F26: 100 | G26: 130 | H26: 160
A27: Insurance & professional services | B27: 10 | C27: 18 | D27: 28 | E27: 42 | F27: 58 | G27: 72 | H27: 88
A28: Other G&A | B28: 15 | C28: 28 | D28: 45 | E28: 75 | F28: 110 | G28: 150 | H28: 190
A29: Total Opex | B29: =SUM(B21:B28) -> 330 | C29: =SUM(C21:C28) -> 584 | D29: =SUM(D21:D28) -> 903 | E29: =SUM(E21:E28) -> 1452 | F29: =SUM(F21:F28) -> 2128 | G29: =SUM(G21:G28) -> 2882 | H29: =SUM(H21:H28) -> 3698
A31: EBITDA | B31: =B17-B29 -> -340 | C31: =C17-C29 -> -307 | D31: =D17-D29 -> 52 | E31: =E17-E29 -> 1003 | F31: =F17-F29 -> 2547 | G31: =G17-G29 -> 5158 | H31: =H17-H29 -> 9212
A32: EBITDA margin % | B32: =IFERROR(B31/B9,0) -> -6.8 | C32: =IFERROR(C31/C9,0) -> -0.80789474 | D32: =IFERROR(D31/D9,0) -> 0.045614035 | E32: =IFERROR(E31/E9,0) -> 0.35821429 | F32: =IFERROR(F31/F9,0) -> 0.48056604 | G32: =IFERROR(G31/G9,0) -> 0.56994475 | H32: =IFERROR(H31/H9,0) -> 0.63750865
A34: Depreciation & Amortisation | B34: 10 | C34: 30 | D34: 60 | E34: 90 | F34: 120 | G34: 150 | H34: 180
A35: Operating Profit (EBIT) | B35: =B31-B34 -> -350 | C35: =C31-C34 -> -337 | D35: =D31-D34 -> -8 | E35: =E31-E34 -> 913 | F35: =F31-F34 -> 2427 | G35: =G31-G34 -> 5008 | H35: =H31-H34 -> 9032
A36: Interest expense (loan) | B36: ='3_Interest_Repayment'!F4/1000 -> 9.62 | C36: ='3_Interest_Repayment'!F5/1000 -> 11.46297 | D36: ='3_Interest_Repayment'!F6/1000 -> 53.36014 | E36: ='3_Interest_Repayment'!F7/1000 -> 42.688112 | F36: ='3_Interest_Repayment'!F8/1000 -> 32.016084 | G36: ='3_Interest_Repayment'!F9/1000 -> 21.344056 | H36: ='3_Interest_Repayment'!F10/1000 -> 10.672028
A37: Profit Before Tax | B37: =B35-B36 -> -359.62 | C37: =C35-C36 -> -348.46297 | D37: =D35-D36 -> -61.36014 | E37: =E35-E36 -> 870.31189 | F37: =F35-F36 -> 2394.9839 | G37: =G35-G36 -> 4986.6559 | H37: =H35-H36 -> 9021.328
A38: Tax (25% on profits, R&D credit Y1-Y3) | B38: =MIN(0,B37)*0 -> 0 | C38: =MIN(0,C37)*0 -> 0 | D38: =MIN(0,D37)*0 -> 0 | E38: =MAX(0,E37)*0.25 -> 217.57797 | F38: =MAX(0,F37)*0.25 -> 598.74598 | G38: =MAX(0,G37)*0.25 -> 1246.664 | H38: =MAX(0,H37)*0.25 -> 2255.332
A39: Net Income | B39: =B37-B38 -> -359.62 | C39: =C37-C38 -> -348.46297 | D39: =D37-D38 -> -61.36014 | E39: =E37-E38 -> 652.73392 | F39: =F37-F38 -> 1796.2379 | G39: =G37-G38 -> 3739.992 | H39: =H37-H38 -> 6765.996

Sheet 5_Cashflow
A1: Cashflow Forecast (Annual £k) - Y1 to Y7
A3: £ thousands | B3: FY26 (Y1) | C3: FY27 (Y2) | D3: FY28 (Y3) | E3: FY29 (Y4) | F3: FY30 (Y5) | G3: FY31 (Y6) | H3: FY32 (Y7)
A4: Operating cashflow
A5: EBITDA (from P&L) | B5: ='4_PnL_Forecast'!B31 -> -340 | C5: ='4_PnL_Forecast'!C31 -> -307 | D5: ='4_PnL_Forecast'!D31 -> 52 | E5: ='4_PnL_Forecast'!E31 -> 1003 | F5: ='4_PnL_Forecast'!F31 -> 2547 | G5: ='4_PnL_Forecast'!G31 -> 5158 | H5: ='4_PnL_Forecast'!H31 -> 9212
A6: Working capital movement | B6: -10 | C6: -25 | D6: -50 | E6: -85 | F6: -140 | G6: -200 | H6: -270
A7: Tax paid | B7: =-'4_PnL_Forecast'!B38 -> 0 | C7: =-'4_PnL_Forecast'!C38 -> 0 | D7: =-'4_PnL_Forecast'!D38 -> 0 | E7: =-'4_PnL_Forecast'!E38 -> -217.57797 | F7: =-'4_PnL_Forecast'!F38 -> -598.74598 | G7: =-'4_PnL_Forecast'!G38 -> -1246.664 | H7: =-'4_PnL_Forecast'!H38 -> -2255.332
A8: Net operating cashflow | B8: =B5+B6+B7 -> -350 | C8: =C5+C6+C7 -> -332 | D8: =D5+D6+D7 -> 2 | E8: =E5+E6+E7 -> 700.42203 | F8: =F5+F6+F7 -> 1808.254 | G8: =G5+G6+G7 -> 3711.336 | H8: =H5+H6+H7 -> 6686.668
A10: Investing cashflow
A11: Capex (lab, hardware, cloud) | B11: -60 | C11: -50 | D11: -45 | E11: -65 | F11: -85 | G11: -110 | H11: -150
A12: Net investing cashflow | B12: =B11 -> -60 | C12: =C11 -> -50 | D12: =D11 -> -45 | E12: =E11 -> -65 | F12: =F11 -> -85 | G12: =G11 -> -110 | H12: =H11 -> -150
A14: Financing cashflow
A15: Loan drawdowns (UKDI/IUK) | B15: ='3_Interest_Repayment'!D4/1000 -> 520 | C15: ='3_Interest_Repayment'!D5/1000 -> 180 | D15: ='3_Interest_Repayment'!D6/1000 -> 0 | E15: ='3_Interest_Repayment'!D7/1000 -> 0 | F15: ='3_Interest_Repayment'!D8/1000 -> 0 | G15: ='3_Interest_Repayment'!D9/1000 -> 0 | H15: ='3_Interest_Repayment'!D10/1000 -> 0
A16: Loan principal repayments | B16: =-'3_Interest_Repayment'!G4/1000 -> 0 | C16: =-'3_Interest_Repayment'!G5/1000 -> 0 | D16: =-'3_Interest_Repayment'!G6/1000 -> -144.21659 | E16: =-'3_Interest_Repayment'!G7/1000 -> -144.21659 | F16: =-'3_Interest_Repayment'!G8/1000 -> -144.21659 | G16: =-'3_Interest_Repayment'!G9/1000 -> -144.21659 | H16: =-'3_Interest_Repayment'!G10/1000 -> -144.21659
A17: Loan interest paid | B17: =-'3_Interest_Repayment'!H4/1000 -> 0 | C17: =-'3_Interest_Repayment'!H5/1000 -> 0 | D17: =-'3_Interest_Repayment'!H6/1000 -> -53.36014 | E17: =-'3_Interest_Repayment'!H7/1000 -> -42.688112 | F17: =-'3_Interest_Repayment'!H8/1000 -> -32.016084 | G17: =-'3_Interest_Repayment'!H9/1000 -> -21.344056 | H17: =-'3_Interest_Repayment'!H10/1000 -> -10.672028
A18: VC follow-on round (£1M total - Y2 inflow on commercial trigger M9) | B18: 0 | C18: 1000 | D18: 0 | E18: 0 | F18: 0 | G18: 0 | H18: 0
A19: Net financing cashflow | B19: =B15+B16+B17+B18 -> 520 | C19: =C15+C16+C17+C18 -> 1180 | D19: =D15+D16+D17+D18 -> -197.57673 | E19: =E15+E16+E17+E18 -> -186.90471 | F19: =F15+F16+F17+F18 -> -176.23268 | G19: =G15+G16+G17+G18 -> -165.56065 | H19: =H15+H16+H17+H18 -> -154.88862
A21: Net change in cash | B21: =B8+B12+B19 -> 110 | C21: =C8+C12+C19 -> 798 | D21: =D8+D12+D19 -> -240.57673 | E21: =E8+E12+E19 -> 448.51732 | F21: =F8+F12+F19 -> 1547.0213 | G21: =G8+G12+G19 -> 3435.7754 | H21: =H8+H12+H19 -> 6381.7794
A22: Opening cash | B22: 0 | C22: =B23 -> 110 | D22: =C23 -> 908 | E22: =D23 -> 667.42327 | F22: =E23 -> 1115.9406 | G22: =F23 -> 2662.9619 | H22: =G23 -> 6098.7373
A23: Closing cash | B23: =B22+B21 -> 110 | C23: =C22+C21 -> 908 | D23: =D22+D21 -> 667.42327 | E23: =E22+E21 -> 1115.9406 | F23: =F22+F21 -> 2662.9619 | G23: =G22+G21 -> 6098.7373 | H23: =H22+H21 -> 12480.517

Sheet 6_Balance_Sheet
A1: Balance Sheet Forecast (£k) - Y1 to Y7
A3: £ thousands | B3: FY26 (Y1) | C3: FY27 (Y2) | D3: FY28 (Y3) | E3: FY29 (Y4) | F3: FY30 (Y5) | G3: FY31 (Y6) | H3: FY32 (Y7)
A4: ASSETS
A5: Cash & equivalents | B5: ='5_Cashflow'!B23 -> 110 | C5: ='5_Cashflow'!C23 -> 908 | D5: ='5_Cashflow'!D23 -> 667.42327 | E5: ='5_Cashflow'!E23 -> 1115.9406 | F5: ='5_Cashflow'!F23 -> 2662.9619 | G5: ='5_Cashflow'!G23 -> 6098.7373 | H5: ='5_Cashflow'!H23 -> 12480.517
A6: Trade receivables | B6: 10 | C6: 40 | D6: 100 | E6: 200 | F6: 360 | G6: 580 | H6: 880
A7: Other current assets | B7: 20 | C7: 25 | D7: 35 | E7: 50 | F7: 70 | G7: 90 | H7: 110
A8: Total current assets | B8: =SUM(B5:B7) -> 140 | C8: =SUM(C5:C7) -> 973 | D8: =SUM(D5:D7) -> 802.42327 | E8: =SUM(E5:E7) -> 1365.9406 | F8: =SUM(F5:F7) -> 3092.9619 | G8: =SUM(G5:G7) -> 6768.7373 | H8: =SUM(H5:H7) -> 13470.517
A9: Property, plant & equipment (net) | B9: 80 | C9: 130 | D9: 180 | E9: 250 | F9: 340 | G9: 460 | H9: 620
A10: Intangibles & capitalised dev | B10: 50 | C10: 130 | D10: 220 | E10: 320 | F10: 430 | G10: 550 | H10: 680
A11: Total non-current assets | B11: =B9+B10 -> 130 | C11: =C9+C10 -> 260 | D11: =D9+D10 -> 400 | E11: =E9+E10 -> 570 | F11: =F9+F10 -> 770 | G11: =G9+G10 -> 1010 | H11: =H9+H10 -> 1300
A12: TOTAL ASSETS | B12: =B8+B11 -> 270 | C12: =C8+C11 -> 1233 | D12: =D8+D11 -> 1202.4233 | E12: =E8+E11 -> 1935.9406 | F12: =F8+F11 -> 3862.9619 | G12: =G8+G11 -> 7778.7373 | H12: =H8+H11 -> 14770.517
A14: LIABILITIES
A15: Trade payables | B15: 12 | C15: 22 | D15: 38 | E15: 60 | F15: 95 | G15: 140 | H15: 200
A16: Accruals & other current liabs | B16: 8 | C16: 18 | D16: 30 | E16: 50 | F16: 75 | G16: 110 | H16: 160
A17: Loan - current portion (excluded per Competition Doc §15: loan is long-term liability) | B17: 0 | C17: 0 | D17: 0 | E17: 0 | F17: 0 | G17: 0 | H17: 0
A18: Total current liabilities | B18: =SUM(B15:B17) -> 20 | C18: =SUM(C15:C17) -> 40 | D18: =SUM(D15:D17) -> 68 | E18: =SUM(E15:E17) -> 110 | F18: =SUM(F15:F17) -> 170 | G18: =SUM(G15:G17) -> 250 | H18: =SUM(H15:H17) -> 360
A19: Loan - non-current portion | B19: =MAX(0,'3_Interest_Repayment'!I4/1000) -> 529.62 | C19: =MAX(0,'3_Interest_Repayment'!I5/1000) -> 721.08297 | D19: =MAX(0,'3_Interest_Repayment'!I6/1000) -> 576.86638 | E19: =MAX(0,'3_Interest_Repayment'!I7/1000) -> 432.64978 | F19: =MAX(0,'3_Interest_Repayment'!I8/1000) -> 288.43319 | G19: =MAX(0,'3_Interest_Repayment'!I9/1000) -> 144.21659 | H19: =MAX(0,'3_Interest_Repayment'!I10/1000) -> 1.1459633e-13
A20: Total non-current liabilities | B20: =B19 -> 529.62 | C20: =C19 -> 721.08297 | D20: =D19 -> 576.86638 | E20: =E19 -> 432.64978 | F20: =F19 -> 288.43319 | G20: =G19 -> 144.21659 | H20: =H19 -> 1.1459633e-13
A21: TOTAL LIABILITIES | B21: =B18+B20 -> 549.62 | C21: =C18+C20 -> 761.08297 | D21: =D18+D20 -> 644.86638 | E21: =E18+E20 -> 542.64978 | F21: =F18+F20 -> 458.43319 | G21: =G18+G20 -> 394.21659 | H21: =H18+H20 -> 360
A23: EQUITY
A24: Share capital + premium | B24: 200 | C24: 1200 | D24: 1200 | E24: 1200 | F24: 1200 | G24: 1200 | H24: 1200
A25: Retained earnings (cumulative) | B25: ='4_PnL_Forecast'!B39 -> -359.62 | C25: =B25+'4_PnL_Forecast'!C39 -> -708.08297 | D25: =C25+'4_PnL_Forecast'!D39 -> -769.44311 | E25: =D25+'4_PnL_Forecast'!E39 -> -116.70919 | F25: =E25+'4_PnL_Forecast'!F39 -> 1679.5287 | G25: =F25+'4_PnL_Forecast'!G39 -> 5419.5207 | H25: =G25+'4_PnL_Forecast'!H39 -> 12185.517
A26: Other reserves (balancing item - share-based payments, IFRS adj) | B26: =B12-B21-B24-B25 -> -120 | C26: =C12-C21-C24-C25 -> -20 | D26: =D12-D21-D24-D25 -> 127 | E26: =E12-E21-E24-E25 -> 310 | F26: =F12-F21-F24-F25 -> 525 | G26: =G12-G21-G24-G25 -> 765 | H26: =H12-H21-H24-H25 -> 1025
A27: TOTAL EQUITY | B27: =B24+B25+B26 -> -279.62 | C27: =C24+C25+C26 -> 471.91703 | D27: =D24+D25+D26 -> 557.55689 | E27: =E24+E25+E26 -> 1393.2908 | F27: =F24+F25+F26 -> 3404.5287 | G27: =G24+G25+G26 -> 7384.5207 | H27: =H24+H25+H26 -> 14410.517
A29: TOTAL LIABILITIES + EQUITY | B29: =B21+B27 -> 270 | C29: =C21+C27 -> 1233 | D29: =D21+D27 -> 1202.4233 | E29: =E21+E27 -> 1935.9406 | F29: =F21+F27 -> 3862.9619 | G29: =G21+G27 -> 7778.7373 | H29: =H21+H27 -> 14770.517
A30: Check: Assets - (Liab+Equity) | B30: =B12-B29 -> 0 | C30: =C12-C29 -> 0 | D30: =D12-D29 -> 0 | E30: =E12-E29 -> 0 | F30: =F12-F29 -> 0 | G30: =G12-G29 -> 0 | H30: =H12-H29 -> 0
A32: Liquidity ratio (Current assets / current liabilities) | B32: =IFERROR(B8/B18,0) -> 7 | C32: =IFERROR(C8/C18,0) -> 24.325 | D32: =IFERROR(D8/D18,0) -> 11.800342 | E32: =IFERROR(E8/E18,0) -> 12.417642 | F32: =IFERROR(F8/F18,0) -> 18.193894 | G32: =IFERROR(G8/G18,0) -> 27.074949 | H32: =IFERROR(H8/H18,0) -> 37.418102
A33: Target ≥ 1.10:1 (Innovate UK requirement)
A34: Note: Per Competition Doc §15 Q&A, the loan principal is a long-term liability and EXCLUDED from liquidity ratio. Innovate UK target ≥ 1.10:1 throughout project.

Sheet 7_Funding_Use
A1: Use of £700K Loan against £880,567 Eligible Project Cost
A3: Category | B3: £ | C3: % of total | D3: Notes
A4: Personnel - internal team (7 named members, 4.2 FTE-equivalent) | B4: 672567 | C4: =B4/$B$12 -> 0.76378856 | D4: 6 existing members + 1 senior hire (CTO, M1-M3 onboarding)
A5: Cloud / sovereign UK lab infrastructure | B5: 50000 | C5: =B5/$B$12 -> 0.056781596 | D5: UK-sovereign cloud + telemetry + threat-intel feed infrastructure
A6: ICS hardware (PLCs, RTUs, HMI test rigs) | B6: 35000 | C6: =B6/$B$12 -> 0.039747117 | D6: Multi-vendor protocol coverage
A7: Pen-test / IEC 62443 assurance (CREST-certified) | B7: 25000 | C7: =B7/$B$12 -> 0.028390798 | D7: Stage-gated assurance M6 / M12 / M18
A8: Travel & customer pilots | B8: 15000 | C8: =B8/$B$12 -> 0.017034479 | D8: 5 UK CNI lighthouses + 2 defence reference engagements
A9: Legal / IP / patents | B9: 10000 | C9: =B9/$B$12 -> 0.011356319 | D9: UK + select international filings
A10: Cyber-insurance & DPIA | B10: 8000 | C10: =B10/$B$12 -> 0.0090850554 | D10: UK GDPR / NIS-aligned
A11: Contingency (~7.4%) | B11: 65000 | C11: =B11/$B$12 -> 0.073816075 | D11: Standard Cycle 1 contingency
A12: TOTAL ELIGIBLE PROJECT COST | B12: =SUM(B4:B11) -> 880567 | C12: =SUM(C4:C11) -> 1
A14: Innovate UK Loan request | B14: 700000 | C14: =B14/B12 -> 0.79494235 | D14: Subsidy intensity (loan / eligible cost) - target ≤ 80%
A15: Matched funding (VC follow-on round £1M, soft interest) | B15: 190000 | D15: £190K of £1M VC round; M9 trigger
A16: TOTAL PROJECT FINANCING (loan + matched) | B16: =B14+B15 -> 890000

Sheet 8_KPI_Dashboard
A1: Key Ratios & Stress Tests
A3: Metric | B3: FY26 (Y1) | C3: FY27 (Y2) | D3: FY28 (Y3) | E3: FY29 (Y4) | F3: FY30 (Y5) | G3: FY31 (Y6) | H3: FY32 (Y7)
A4: Revenue (£k) | B4: ='4_PnL_Forecast'!B9 -> 50 | C4: ='4_PnL_Forecast'!C9 -> 380 | D4: ='4_PnL_Forecast'!D9 -> 1140 | E4: ='4_PnL_Forecast'!E9 -> 2800 | F4: ='4_PnL_Forecast'!F9 -> 5300 | G4: ='4_PnL_Forecast'!G9 -> 9050 | H4: ='4_PnL_Forecast'!H9 -> 14450
A5: Revenue YoY growth % | B5: n/a | C5: =IFERROR('4_PnL_Forecast'!C9/'4_PnL_Forecast'!B9-1,0) -> 6.6 | D5: =IFERROR('4_PnL_Forecast'!D9/'4_PnL_Forecast'!C9-1,0) -> 2 | E5: =IFERROR('4_PnL_Forecast'!E9/'4_PnL_Forecast'!D9-1,0) -> 1.4561404 | F5: =IFERROR('4_PnL_Forecast'!F9/'4_PnL_Forecast'!E9-1,0) -> 0.89285714 | G5: =IFERROR('4_PnL_Forecast'!G9/'4_PnL_Forecast'!F9-1,0) -> 0.70754717 | H5: =IFERROR('4_PnL_Forecast'!H9/'4_PnL_Forecast'!G9-1,0) -> 0.59668508
A6: Gross margin % | B6: =IFERROR('4_PnL_Forecast'!B17/'4_PnL_Forecast'!B9,0) -> -0.2 | C6: =IFERROR('4_PnL_Forecast'!C17/'4_PnL_Forecast'!C9,0) -> 0.72894737 | D6: =IFERROR('4_PnL_Forecast'!D17/'4_PnL_Forecast'!D9,0) -> 0.8377193 | E6: =IFERROR('4_PnL_Forecast'!E17/'4_PnL_Forecast'!E9,0) -> 0.87678571 | F6: =IFERROR('4_PnL_Forecast'!F17/'4_PnL_Forecast'!F9,0) -> 0.88207547 | G6: =IFERROR('4_PnL_Forecast'!G17/'4_PnL_Forecast'!G9,0) -> 0.88839779 | H6: =IFERROR('4_PnL_Forecast'!H17/'4_PnL_Forecast'!H9,0) -> 0.89342561
A7: EBITDA margin % | B7: =IFERROR('4_PnL_Forecast'!B31/'4_PnL_Forecast'!B9,0) -> -6.8 | C7: =IFERROR('4_PnL_Forecast'!C31/'4_PnL_Forecast'!C9,0) -> -0.80789474 | D7: =IFERROR('4_PnL_Forecast'!D31/'4_PnL_Forecast'!D9,0) -> 0.045614035 | E7: =IFERROR('4_PnL_Forecast'!E31/'4_PnL_Forecast'!E9,0) -> 0.35821429 | F7: =IFERROR('4_PnL_Forecast'!F31/'4_PnL_Forecast'!F9,0) -> 0.48056604 | G7: =IFERROR('4_PnL_Forecast'!G31/'4_PnL_Forecast'!G9,0) -> 0.56994475 | H7: =IFERROR('4_PnL_Forecast'!H31/'4_PnL_Forecast'!H9,0) -> 0.63750865
A8: Closing cash (£k) | B8: ='5_Cashflow'!B23 -> 110 | C8: ='5_Cashflow'!C23 -> 908 | D8: ='5_Cashflow'!D23 -> 667.42327 | E8: ='5_Cashflow'!E23 -> 1115.9406 | F8: ='5_Cashflow'!F23 -> 2662.9619 | G8: ='5_Cashflow'!G23 -> 6098.7373 | H8: ='5_Cashflow'!H23 -> 12480.517
A9: Liquidity ratio | B9: ='6_Balance_Sheet'!B32 -> 7 | C9: ='6_Balance_Sheet'!C32 -> 24.325 | D9: ='6_Balance_Sheet'!D32 -> 11.800342 | E9: ='6_Balance_Sheet'!E32 -> 12.417642 | F9: ='6_Balance_Sheet'!F32 -> 18.193894 | G9: ='6_Balance_Sheet'!G32 -> 27.074949 | H9: ='6_Balance_Sheet'!H32 -> 37.418102
A10: Debt service coverage (EBITDA / debt service) | B10: =IFERROR('4_PnL_Forecast'!B31/MAX(1,('3_Interest_Repayment'!G4+'3_Interest_Repayment'!H4)/1000),0) -> -340 | C10: =IFERROR('4_PnL_Forecast'!C31/MAX(1,('3_Interest_Repayment'!G5+'3_Interest_Repayment'!H5)/1000),0) -> -307 | D10: =IFERROR('4_PnL_Forecast'!D31/MAX(1,('3_Interest_Repayment'!G6+'3_Interest_Repayment'!H6)/1000),0) -> 0.26318888 | E10: =IFERROR('4_PnL_Forecast'!E31/MAX(1,('3_Interest_Repayment'!G7+'3_Interest_Repayment'!H7)/1000),0) -> 5.366371 | F10: =IFERROR('4_PnL_Forecast'!F31/MAX(1,('3_Interest_Repayment'!G8+'3_Interest_Repayment'!H8)/1000),0) -> 14.452484 | G10: =IFERROR('4_PnL_Forecast'!G31/MAX(1,('3_Interest_Repayment'!G9+'3_Interest_Repayment'!H9)/1000),0) -> 31.154746 | H10: =IFERROR('4_PnL_Forecast'!H31/MAX(1,('3_Interest_Repayment'!G10+'3_Interest_Repayment'!H10)/1000),0) -> 59.474995
A12: Stress Test - Revenue −30% scenario
A13: Stressed revenue (−30%) | B13: ='4_PnL_Forecast'!B9*0.7 -> 35 | C13: ='4_PnL_Forecast'!C9*0.7 -> 266 | D13: ='4_PnL_Forecast'!D9*0.7 -> 798 | E13: ='4_PnL_Forecast'!E9*0.7 -> 1960 | F13: ='4_PnL_Forecast'!F9*0.7 -> 3710 | G13: ='4_PnL_Forecast'!G9*0.7 -> 6335 | H13: ='4_PnL_Forecast'!H9*0.7 -> 10115
A14: Stressed gross profit (assume same GM) | B14: =B13*IFERROR('4_PnL_Forecast'!B17/'4_PnL_Forecast'!B9,0) -> -7 | C14: =C13*IFERROR('4_PnL_Forecast'!C17/'4_PnL_Forecast'!C9,0) -> 193.9 | D14: =D13*IFERROR('4_PnL_Forecast'!D17/'4_PnL_Forecast'!D9,0) -> 668.5 | E14: =E13*IFERROR('4_PnL_Forecast'!E17/'4_PnL_Forecast'!E9,0) -> 1718.5 | F14: =F13*IFERROR('4_PnL_Forecast'!F17/'4_PnL_Forecast'!F9,0) -> 3272.5 | G14: =G13*IFERROR('4_PnL_Forecast'!G17/'4_PnL_Forecast'!G9,0) -> 5628 | H14: =H13*IFERROR('4_PnL_Forecast'!H17/'4_PnL_Forecast'!H9,0) -> 9037
A15: Stressed EBITDA | B15: =B14-'4_PnL_Forecast'!B29 -> -337 | C15: =C14-'4_PnL_Forecast'!C29 -> -390.1 | D15: =D14-'4_PnL_Forecast'!D29 -> -234.5 | E15: =E14-'4_PnL_Forecast'!E29 -> 266.5 | F15: =F14-'4_PnL_Forecast'!F29 -> 1144.5 | G15: =G14-'4_PnL_Forecast'!G29 -> 2746 | H15: =H14-'4_PnL_Forecast'!H29 -> 5339
A16: Stressed DSCR | B16: =IFERROR(B15/MAX(1,('3_Interest_Repayment'!G4+'3_Interest_Repayment'!H4)/1000),0) -> -337 | C16: =IFERROR(C15/MAX(1,('3_Interest_Repayment'!G5+'3_Interest_Repayment'!H5)/1000),0) -> -390.1 | D16: =IFERROR(D15/MAX(1,('3_Interest_Repayment'!G6+'3_Interest_Repayment'!H6)/1000),0) -> -1.1868806 | E16: =IFERROR(E15/MAX(1,('3_Interest_Repayment'!G7+'3_Interest_Repayment'!H7)/1000),0) -> 1.4258603 | F16: =IFERROR(F15/MAX(1,('3_Interest_Repayment'!G8+'3_Interest_Repayment'!H8)/1000),0) -> 6.4942553 | G16: =IFERROR(G15/MAX(1,('3_Interest_Repayment'!G9+'3_Interest_Repayment'!H9)/1000),0) -> 16.586067 | H16: =IFERROR(H15/MAX(1,('3_Interest_Repayment'!G10+'3_Interest_Repayment'!H10)/1000),0) -> 34.46993
A18: Compliance Summary (Innovate UK gates)
A19: Subsidy intensity (GGE / total eligible cost) | B19: ='1_Cover_Assumptions'!B51 -> 0.1192414 | D19: Target ≤ 45% (small business per Competition Doc §9.1)
A20: Min liquidity ratio across project (Y1-Y3) | B20: =MIN('6_Balance_Sheet'!B32:H32) -> 7 | D20: Target ≥ 1.10
